{
 "cells": [
  {
   "cell_type": "code",
   "execution_count": 3,
   "metadata": {},
   "outputs": [
    {
     "data": {
      "text/html": [
       "<div>\n",
       "<style scoped>\n",
       "    .dataframe tbody tr th:only-of-type {\n",
       "        vertical-align: middle;\n",
       "    }\n",
       "\n",
       "    .dataframe tbody tr th {\n",
       "        vertical-align: top;\n",
       "    }\n",
       "\n",
       "    .dataframe thead th {\n",
       "        text-align: right;\n",
       "    }\n",
       "</style>\n",
       "<table border=\"1\" class=\"dataframe\">\n",
       "  <thead>\n",
       "    <tr style=\"text-align: right;\">\n",
       "      <th></th>\n",
       "      <th>mgs</th>\n",
       "      <th>count</th>\n",
       "    </tr>\n",
       "  </thead>\n",
       "  <tbody>\n",
       "    <tr>\n",
       "      <th>0</th>\n",
       "      <td>AMQP server on 192.168.15.245:5672 is unreachable: (0, 0): (320) CONNECTION_FORCED - broker forced connection closure with reason 'shutdown'. Trying again in 1 seconds.: amqp.exceptions.ConnectionForced: (0, 0): (320) CONNECTION_FORCED - broker forced connection closure with reason 'shutdown'</td>\n",
       "      <td>1</td>\n",
       "    </tr>\n",
       "    <tr>\n",
       "      <th>1</th>\n",
       "      <td>AMQP server on 192.168.15.245:5672 is unreachable: &lt;RecoverableConnectionError: unknown error&gt;. Trying again in 1 seconds.: amqp.exceptions.RecoverableConnectionError: &lt;RecoverableConnectionError: unknown error&gt;</td>\n",
       "      <td>3695</td>\n",
       "    </tr>\n",
       "    <tr>\n",
       "      <th>2</th>\n",
       "      <td>AMQP server on 192.168.15.245:5672 is unreachable: Basic.cancel: (0) 1. Trying again in 1 seconds.: amqp.exceptions.ConsumerCancelled: Basic.cancel: (0) 1</td>\n",
       "      <td>1</td>\n",
       "    </tr>\n",
       "    <tr>\n",
       "      <th>3</th>\n",
       "      <td>AMQP server on 192.168.15.245:5672 is unreachable: Basic.cancel: (0) 3. Trying again in 1 seconds.: amqp.exceptions.ConsumerCancelled: Basic.cancel: (0) 3</td>\n",
       "      <td>1</td>\n",
       "    </tr>\n",
       "    <tr>\n",
       "      <th>4</th>\n",
       "      <td>AMQP server on 192.168.15.245:5672 is unreachable: Server unexpectedly closed connection. Trying again in 2 seconds.: OSError: Server unexpectedly closed connection</td>\n",
       "      <td>3679</td>\n",
       "    </tr>\n",
       "    <tr>\n",
       "      <th>5</th>\n",
       "      <td>AMQP server on 192.168.15.245:5672 is unreachable: Server unexpectedly closed connection. Trying again in 4 seconds.: OSError: Server unexpectedly closed connection</td>\n",
       "      <td>3675</td>\n",
       "    </tr>\n",
       "    <tr>\n",
       "      <th>6</th>\n",
       "      <td>AMQP server on 192.168.15.245:5672 is unreachable: Too many heartbeats missed. Trying again in 1 seconds.: amqp.exceptions.ConnectionForced: Too many heartbeats missed</td>\n",
       "      <td>1</td>\n",
       "    </tr>\n",
       "    <tr>\n",
       "      <th>7</th>\n",
       "      <td>Backup running in single process mode.</td>\n",
       "      <td>2</td>\n",
       "    </tr>\n",
       "    <tr>\n",
       "      <th>8</th>\n",
       "      <td>Connection failed: Server unexpectedly closed connection (retrying in 1.0 seconds): OSError: Server unexpectedly closed connection</td>\n",
       "      <td>2</td>\n",
       "    </tr>\n",
       "    <tr>\n",
       "      <th>9</th>\n",
       "      <td>Connection failed: Server unexpectedly closed connection (retrying in 11.0 seconds): OSError: Server unexpectedly closed connection</td>\n",
       "      <td>2</td>\n",
       "    </tr>\n",
       "    <tr>\n",
       "      <th>10</th>\n",
       "      <td>Connection failed: Server unexpectedly closed connection (retrying in 13.0 seconds): OSError: Server unexpectedly closed connection</td>\n",
       "      <td>2</td>\n",
       "    </tr>\n",
       "    <tr>\n",
       "      <th>11</th>\n",
       "      <td>Connection failed: Server unexpectedly closed connection (retrying in 15.0 seconds): OSError: Server unexpectedly closed connection</td>\n",
       "      <td>2</td>\n",
       "    </tr>\n",
       "    <tr>\n",
       "      <th>12</th>\n",
       "      <td>Connection failed: Server unexpectedly closed connection (retrying in 17.0 seconds): OSError: Server unexpectedly closed connection</td>\n",
       "      <td>2</td>\n",
       "    </tr>\n",
       "    <tr>\n",
       "      <th>13</th>\n",
       "      <td>Connection failed: Server unexpectedly closed connection (retrying in 19.0 seconds): OSError: Server unexpectedly closed connection</td>\n",
       "      <td>2</td>\n",
       "    </tr>\n",
       "    <tr>\n",
       "      <th>14</th>\n",
       "      <td>Connection failed: Server unexpectedly closed connection (retrying in 21.0 seconds): OSError: Server unexpectedly closed connection</td>\n",
       "      <td>2</td>\n",
       "    </tr>\n",
       "    <tr>\n",
       "      <th>15</th>\n",
       "      <td>Connection failed: Server unexpectedly closed connection (retrying in 23.0 seconds): OSError: Server unexpectedly closed connection</td>\n",
       "      <td>2</td>\n",
       "    </tr>\n",
       "    <tr>\n",
       "      <th>16</th>\n",
       "      <td>Connection failed: Server unexpectedly closed connection (retrying in 25.0 seconds): OSError: Server unexpectedly closed connection</td>\n",
       "      <td>2</td>\n",
       "    </tr>\n",
       "    <tr>\n",
       "      <th>17</th>\n",
       "      <td>Connection failed: Server unexpectedly closed connection (retrying in 27.0 seconds): OSError: Server unexpectedly closed connection</td>\n",
       "      <td>2</td>\n",
       "    </tr>\n",
       "    <tr>\n",
       "      <th>18</th>\n",
       "      <td>Connection failed: Server unexpectedly closed connection (retrying in 29.0 seconds): OSError: Server unexpectedly closed connection</td>\n",
       "      <td>2</td>\n",
       "    </tr>\n",
       "    <tr>\n",
       "      <th>19</th>\n",
       "      <td>Connection failed: Server unexpectedly closed connection (retrying in 3.0 seconds): OSError: Server unexpectedly closed connection</td>\n",
       "      <td>2</td>\n",
       "    </tr>\n",
       "    <tr>\n",
       "      <th>20</th>\n",
       "      <td>Connection failed: Server unexpectedly closed connection (retrying in 31.0 seconds): OSError: Server unexpectedly closed connection</td>\n",
       "      <td>812</td>\n",
       "    </tr>\n",
       "    <tr>\n",
       "      <th>21</th>\n",
       "      <td>Connection failed: Server unexpectedly closed connection (retrying in 5.0 seconds): OSError: Server unexpectedly closed connection</td>\n",
       "      <td>2</td>\n",
       "    </tr>\n",
       "    <tr>\n",
       "      <th>22</th>\n",
       "      <td>Connection failed: Server unexpectedly closed connection (retrying in 7.0 seconds): OSError: Server unexpectedly closed connection</td>\n",
       "      <td>2</td>\n",
       "    </tr>\n",
       "    <tr>\n",
       "      <th>23</th>\n",
       "      <td>Connection failed: Server unexpectedly closed connection (retrying in 9.0 seconds): OSError: Server unexpectedly closed connection</td>\n",
       "      <td>2</td>\n",
       "    </tr>\n",
       "    <tr>\n",
       "      <th>24</th>\n",
       "      <td>Connection reset by peer</td>\n",
       "      <td>1</td>\n",
       "    </tr>\n",
       "    <tr>\n",
       "      <th>25</th>\n",
       "      <td>ECONNREFUSED</td>\n",
       "      <td>42</td>\n",
       "    </tr>\n",
       "    <tr>\n",
       "      <th>26</th>\n",
       "      <td>Error during BackupManager.publish_service_capabilities: oslo_messaging.exceptions.MessageDeliveryFailure: Unable to connect to AMQP server on 192.168.15.245:5672 after inf tries: (0, 0): (541) INTERNAL_ERROR</td>\n",
       "      <td>2</td>\n",
       "    </tr>\n",
       "    <tr>\n",
       "      <th>27</th>\n",
       "      <td>Failed to publish message to topic 'cinder-scheduler_fanout': (0, 0): (541) INTERNAL_ERROR: amqp.exceptions.InternalError: (0, 0): (541) INTERNAL_ERROR</td>\n",
       "      <td>2</td>\n",
       "    </tr>\n",
       "    <tr>\n",
       "      <th>28</th>\n",
       "      <td>Manager for service cinder-backup node05 is reporting problems, not sending heartbeat. Service will appear \"down\".</td>\n",
       "      <td>70099</td>\n",
       "    </tr>\n",
       "    <tr>\n",
       "      <th>29</th>\n",
       "      <td>RADOS object not found (error calling conf_read_file)</td>\n",
       "      <td>8</td>\n",
       "    </tr>\n",
       "    <tr>\n",
       "      <th>30</th>\n",
       "      <td>The broker has blocked the connection: connection blocked, see broker logs</td>\n",
       "      <td>4</td>\n",
       "    </tr>\n",
       "    <tr>\n",
       "      <th>31</th>\n",
       "      <td>Unable to connect to AMQP server on 192.168.15.245:5672 after inf tries: (0, 0): (541) INTERNAL_ERROR: amqp.exceptions.InternalError: (0, 0): (541) INTERNAL_ERROR</td>\n",
       "      <td>2</td>\n",
       "    </tr>\n",
       "  </tbody>\n",
       "</table>\n",
       "</div>"
      ],
      "text/plain": [
       "                                                                                                                                                                                                                                                                                                      mgs  \\\n",
       "0   AMQP server on 192.168.15.245:5672 is unreachable: (0, 0): (320) CONNECTION_FORCED - broker forced connection closure with reason 'shutdown'. Trying again in 1 seconds.: amqp.exceptions.ConnectionForced: (0, 0): (320) CONNECTION_FORCED - broker forced connection closure with reason 'shutdown'   \n",
       "1                                                                                     AMQP server on 192.168.15.245:5672 is unreachable: <RecoverableConnectionError: unknown error>. Trying again in 1 seconds.: amqp.exceptions.RecoverableConnectionError: <RecoverableConnectionError: unknown error>   \n",
       "2                                                                                                                                              AMQP server on 192.168.15.245:5672 is unreachable: Basic.cancel: (0) 1. Trying again in 1 seconds.: amqp.exceptions.ConsumerCancelled: Basic.cancel: (0) 1   \n",
       "3                                                                                                                                              AMQP server on 192.168.15.245:5672 is unreachable: Basic.cancel: (0) 3. Trying again in 1 seconds.: amqp.exceptions.ConsumerCancelled: Basic.cancel: (0) 3   \n",
       "4                                                                                                                                    AMQP server on 192.168.15.245:5672 is unreachable: Server unexpectedly closed connection. Trying again in 2 seconds.: OSError: Server unexpectedly closed connection   \n",
       "5                                                                                                                                    AMQP server on 192.168.15.245:5672 is unreachable: Server unexpectedly closed connection. Trying again in 4 seconds.: OSError: Server unexpectedly closed connection   \n",
       "6                                                                                                                                 AMQP server on 192.168.15.245:5672 is unreachable: Too many heartbeats missed. Trying again in 1 seconds.: amqp.exceptions.ConnectionForced: Too many heartbeats missed   \n",
       "7                                                                                                                                                                                                                                                                  Backup running in single process mode.   \n",
       "8                                                                                                                                                                      Connection failed: Server unexpectedly closed connection (retrying in 1.0 seconds): OSError: Server unexpectedly closed connection   \n",
       "9                                                                                                                                                                     Connection failed: Server unexpectedly closed connection (retrying in 11.0 seconds): OSError: Server unexpectedly closed connection   \n",
       "10                                                                                                                                                                    Connection failed: Server unexpectedly closed connection (retrying in 13.0 seconds): OSError: Server unexpectedly closed connection   \n",
       "11                                                                                                                                                                    Connection failed: Server unexpectedly closed connection (retrying in 15.0 seconds): OSError: Server unexpectedly closed connection   \n",
       "12                                                                                                                                                                    Connection failed: Server unexpectedly closed connection (retrying in 17.0 seconds): OSError: Server unexpectedly closed connection   \n",
       "13                                                                                                                                                                    Connection failed: Server unexpectedly closed connection (retrying in 19.0 seconds): OSError: Server unexpectedly closed connection   \n",
       "14                                                                                                                                                                    Connection failed: Server unexpectedly closed connection (retrying in 21.0 seconds): OSError: Server unexpectedly closed connection   \n",
       "15                                                                                                                                                                    Connection failed: Server unexpectedly closed connection (retrying in 23.0 seconds): OSError: Server unexpectedly closed connection   \n",
       "16                                                                                                                                                                    Connection failed: Server unexpectedly closed connection (retrying in 25.0 seconds): OSError: Server unexpectedly closed connection   \n",
       "17                                                                                                                                                                    Connection failed: Server unexpectedly closed connection (retrying in 27.0 seconds): OSError: Server unexpectedly closed connection   \n",
       "18                                                                                                                                                                    Connection failed: Server unexpectedly closed connection (retrying in 29.0 seconds): OSError: Server unexpectedly closed connection   \n",
       "19                                                                                                                                                                     Connection failed: Server unexpectedly closed connection (retrying in 3.0 seconds): OSError: Server unexpectedly closed connection   \n",
       "20                                                                                                                                                                    Connection failed: Server unexpectedly closed connection (retrying in 31.0 seconds): OSError: Server unexpectedly closed connection   \n",
       "21                                                                                                                                                                     Connection failed: Server unexpectedly closed connection (retrying in 5.0 seconds): OSError: Server unexpectedly closed connection   \n",
       "22                                                                                                                                                                     Connection failed: Server unexpectedly closed connection (retrying in 7.0 seconds): OSError: Server unexpectedly closed connection   \n",
       "23                                                                                                                                                                     Connection failed: Server unexpectedly closed connection (retrying in 9.0 seconds): OSError: Server unexpectedly closed connection   \n",
       "24                                                                                                                                                                                                                                                                               Connection reset by peer   \n",
       "25                                                                                                                                                                                                                                                                                           ECONNREFUSED   \n",
       "26                                                                                       Error during BackupManager.publish_service_capabilities: oslo_messaging.exceptions.MessageDeliveryFailure: Unable to connect to AMQP server on 192.168.15.245:5672 after inf tries: (0, 0): (541) INTERNAL_ERROR   \n",
       "27                                                                                                                                                Failed to publish message to topic 'cinder-scheduler_fanout': (0, 0): (541) INTERNAL_ERROR: amqp.exceptions.InternalError: (0, 0): (541) INTERNAL_ERROR   \n",
       "28                                                                                                                                                                                     Manager for service cinder-backup node05 is reporting problems, not sending heartbeat. Service will appear \"down\".   \n",
       "29                                                                                                                                                                                                                                                  RADOS object not found (error calling conf_read_file)   \n",
       "30                                                                                                                                                                                                                             The broker has blocked the connection: connection blocked, see broker logs   \n",
       "31                                                                                                                                     Unable to connect to AMQP server on 192.168.15.245:5672 after inf tries: (0, 0): (541) INTERNAL_ERROR: amqp.exceptions.InternalError: (0, 0): (541) INTERNAL_ERROR   \n",
       "\n",
       "    count  \n",
       "0       1  \n",
       "1    3695  \n",
       "2       1  \n",
       "3       1  \n",
       "4    3679  \n",
       "5    3675  \n",
       "6       1  \n",
       "7       2  \n",
       "8       2  \n",
       "9       2  \n",
       "10      2  \n",
       "11      2  \n",
       "12      2  \n",
       "13      2  \n",
       "14      2  \n",
       "15      2  \n",
       "16      2  \n",
       "17      2  \n",
       "18      2  \n",
       "19      2  \n",
       "20    812  \n",
       "21      2  \n",
       "22      2  \n",
       "23      2  \n",
       "24      1  \n",
       "25     42  \n",
       "26      2  \n",
       "27      2  \n",
       "28  70099  \n",
       "29      8  \n",
       "30      4  \n",
       "31      2  "
      ]
     },
     "execution_count": 3,
     "metadata": {},
     "output_type": "execute_result"
    }
   ],
   "source": [
    "import os\n",
    "import re\n",
    "from datetime import datetime\n",
    "\n",
    "import re\n",
    "import pandas as pd\n",
    "\n",
    "log_directory = 'logs' # Replace with the correct Openstack Logs folder path\n",
    "\n",
    "target_date_time = datetime(2023, 10, 20, 12, 00, 00)  # Replace with your desired date and time\n",
    "\n",
    "# print(\"\")\n",
    "# print(\"Openstack Log Analyser\")\n",
    "# print(\"Enter with year, month, day, hour, minutes and seconds. The logs will gather from this date onwards\")\n",
    "# set_date_time_ge = int(input(\"sample format: 2023, 10, 30, 12, 00, 00: \"))\n",
    "# print(set_date_time_ge)\n",
    "# target_date_time = datetime(set_date_time_ge) \n",
    "\n",
    "error_patterns = [\n",
    "    r'ERROR',  # Add more error patterns as needed\n",
    "    r'Exception',\n",
    "    r'failed',\n",
    "]\n",
    "\n",
    "for root, dirs, files in os.walk(log_directory):\n",
    "    for file in files:\n",
    "        if file.endswith('.log'):\n",
    "            log_file_path = os.path.join(root, file)\n",
    "            with open(log_file_path, 'r') as log_file:\n",
    "                for line_number, line in enumerate(log_file, start=1):\n",
    "                    log_timestamp = re.search(r'\\d{4}-\\d{2}-\\d{2} \\d{2}:\\d{2}:\\d{2}', line)\n",
    "                    if log_timestamp:\n",
    "                        log_timestamp = datetime.strptime(log_timestamp.group(), '%Y-%m-%d %H:%M:%S')\n",
    "                        if log_timestamp >= target_date_time:\n",
    "                            if any(re.search(pattern, line) for pattern in error_patterns):\n",
    "                                # print(f'Error message found in: {log_file_path} (Line {line_number}): {line}')\n",
    "                                arr_errors = []\n",
    "                                for line in log_file:\n",
    "                                    if re.search('ERROR', line) and re.search('] ', line):\n",
    "                                        arr_errors.append( line.split('] ')[-1].strip() )\n",
    "                            pd.set_option('display.max_colwidth', None)\n",
    "                            df = pd.DataFrame(arr_errors)\n",
    "                            df.columns = ['mgs']\n",
    "                            df = df.groupby(['mgs']).size().reset_index()\n",
    "                            df.columns = ['mgs', 'count']\n",
    "df                            "
   ]
  }
 ],
 "metadata": {
  "kernelspec": {
   "display_name": ".venv",
   "language": "python",
   "name": "python3"
  },
  "language_info": {
   "codemirror_mode": {
    "name": "ipython",
    "version": 3
   },
   "file_extension": ".py",
   "mimetype": "text/x-python",
   "name": "python",
   "nbconvert_exporter": "python",
   "pygments_lexer": "ipython3",
   "version": "3.11.6"
  }
 },
 "nbformat": 4,
 "nbformat_minor": 2
}
